Workbook

Sheet Intro and Instructions
D1: Intro & Instructions
A4: Name: | B4: NAME HERE | D4: Trade Exit Codes
A5: Start Date: | D5: S1 | E5: Hit Initial Stop Loss 1
A6: End Date: | D6: S2+ | E6: Hit Trailing Stop 2+
A7: Initial Balance: | B7: 10000 | D7: ME | E7: Manual Exit
D8: T | E8: Target Hit
D10: Mood/Confidence Codes
D11: 1 | E11: Extremely Unhappy / Stressed
D12: 2 | E12: Rather Unhappy / Discontent
D13: 3 | E13: Neutral
D14: 4 | E14: Happy / Confident
D15: 5 | E15: Extremely Happy, calm and confident
D17: B | E17: Buy / Long
D18: S | E18: Sell / Short
A20: Example
A21: Asset | B21: Date | C21: Mood (1-5) | D21: B/S | E21: Size (K) | F21: Open @ | G21: Stop 1 | H21: Stop 2 | I21: Stop 3 | J21: Target | K21: Initial Risk | L21: Initial Reward | M21: INITIAL RRR | N21: ACTUAL RRR | P21: Closed @ | Q21: Date/Time | R21: Exit | S21: ME + Hit Stop | T21: ME + Hit Target | U21: P/L gained or lost | V21: Duration (Hours) | W21: Net P/L (£) | X21: P/L (Pips) | Y21: Running P/L | Z21: Trade Sheet Name
A22: GBPUSD | B22: 42439.403 | C22: 3 | D22: B | E22: 50 | F22: 1.2424 | G22: 1.23879 | J22: 1.2466 | K22: -145.38 | L22: 169.14 | M22: =ABS(L22/K22) -> 1.1634338 | N22: =IF(W22>0,W22/ABS(K22),L22/ABS(W22)) -> 1.1443115 | O22: =IF(F22<=3,10000,IF(AND(3<F22,F22<=1500),100,1)) -> 10000 | P22: 1.24666 | Q22: 42439.524 | R22: T | U22: =IF(T22="Y",W22-L22,IF(S22="Y",W22-K22)) -> FALSE | V22: =(Q22-B22)*24 -> 2.9166667 | W22: 166.36 | X22: =IF(D22="B",((P22-F22)*O22),((F22-P22)*O22)) -> 42.6 | Y22: =B7+W22 -> 10166.36 | Z22: =IF(A22<>"",A22&" - "&TEXT(B22, "gg/mm/aaaa hh:mm"),"") -> GBPUSD - /03/Thursday 09:40
A23: START OFFICIAL TRACKING ON 'TRADE BLOTTER' WORKSHEET

Sheet Trade Blotter
D1: TRADE BLOTTER | L1: DO NOT TYPE IN ANY GREY CELLS!!!
A2: SAMPLE TRADES | U2: Trade Exit | AA2: Trading Statistics | AE2: Trade Sheets | AF2: Example Points System
A3: Asset | B3: Date | C3: Mood (1-5) | D3: B/S | E3: £/pip | F3: Open @ | G3: Stop 1 | H3: Pip Risk | I3: Stop 2 | J3: Pip Risk | K3: Stop 3 | L3: Pip Risk | M3: Stop 3 | N3: Pip Risk | O3: Target | P3: Pip Risk | Q3: Initial Risk | R3: Initial Reward | S3: INITIAL RRR | T3: ACTUAL RRR | U3: Closed @ | V3: Date/Time | W3: Exit | X3: ME + Hit Stop | Y3: ME + Hit Target | Z3: P/L gained or lost | AA3: Duration (Hours) | AB3: Net P/L (£) | AC3: P/L (Pips) | AD3: Running P/L | AE3: Trade Sheet Name | AF3: Patterns (10) | AG3: S/R (10) | AH3: Candles (3) | AI3: RSI (3) | AJ3: Fibs (3) | AK3: TOTAL
A4: GBPUSD | B4: 43900.403 | C4: 3 | D4: B | E4: 2.7 | F4: 1.2424 | G4: 1.23879 | H4: 1.2 | O4: 1.2466 | P4: =IF(D4="B",O4-F4,IF(D4="S",F4-O4))*10000 -> 42 | Q4: =-(E4*H4) -> -3.24 | R4: =E4*P4 -> 113.4 | S4: =ABS(R4/Q4) -> 35 | T4: =IF(AB4>0,AB4/ABS(Q4)) -> 17.669753 | U4: 1.2445 | V4: 43900.524 | W4: S2+ | Z4: =IF(Y4="Y",AB4-R4,IF(X4="Y",AB4-Q4)) -> FALSE | AA4: =(V4-B4)*24 -> 2.9166667 | AB4: 57.25 | AE4: =IF(A4<>"",A4&" - "&TEXT(B4, "dd/mm/yyyy hh:mm"),"") -> GBPUSD - 10/03/2020 09:40 | AF4: 8 | AG4: 5 | AH4: 3 | AI4: 0 | AJ4: 0 | AK4: =SUM(AF4:AJ4) -> 16
A5: EURUSD | B5: 43903.544 | C5: 5 | D5: S | E5: 4.7 | F5: 1.06575 | G5: 1.06786 | H5: 21.1 | O5: 1.0627 | P5: =IF(D5="B",O5-F5,IF(D5="S",F5-O5))*10000 -> 30.5 | Q5: =-(E5*H5) -> -99.17 | R5: =E5*P5 -> 143.35 | S5: =ABS(R5/Q5) -> 1.4454976 | T5: =IF(AB5>0,AB5/ABS(Q5)) -> FALSE | U5: 1.06787 | V5: 43903.649 | W5: S1 | Z5: =IF(Y5="Y",AB5-R5,IF(X5="Y",AB5-Q5)) -> FALSE | AA5: =(V5-B5)*24 -> 2.5166667 | AB5: -90.48 | AE5: =IF(A5<>"",A5&" - "&TEXT(B5, "dd/mm/yyyy hh:mm"),"") -> EURUSD - 13/03/2020 13:04 | AF5: 8 | AG5: 5 | AH5: 3 | AI5: 0 | AJ5: 0 | AK5: =SUM(AF5:AJ5) -> 16
A6: GBPUSD | B6: 43912.58 | C6: 3 | D6: B | E6: 2 | F6: 1.4451 | G6: 1.4403 | H6: 48 | O6: 1.456 | P6: =IF(D6="B",O6-F6,IF(D6="S",F6-O6))*10000 -> 109 | Q6: =-(E6*H6) -> -96 | R6: =E6*P6 -> 218 | S6: =ABS(R6/Q6) -> 2.2708333 | T6: =IF(AB6>0,AB6/ABS(Q6)) -> 1.1666667 | U6: 1.451 | V6: 43913.684 | W6: ME | Y6: y | Z6: =IF(Y6="Y",AB6-R6,IF(X6="Y",AB6-Q6)) -> -106 | AA6: =(V6-B6)*24 -> 26.5 | AB6: 112 | AE6: =IF(A6<>"",A6&" - "&TEXT(B6, "dd/mm/yyyy hh:mm"),"") -> GBPUSD - 22/03/2020 13:55 | AF6: 8 | AG6: 5 | AH6: 3 | AI6: 0 | AJ6: 0 | AK6: =SUM(AF6:AJ6) -> 16
A7: DAX | B7: 43904.333 | C7: 4 | D7: S | E7: 3.2 | F7: 11987.61 | G7: 12017.87 | H7: 30.26 | I7: 11989.59 | O7: 11934.98 | P7: =IF(D7="B",O7-F7,IF(D7="S",F7-O7)) -> 52.63 | Q7: =-(E7*H7) -> -96.832 | R7: =E7*P7 -> 168.416 | S7: =ABS(R7/Q7) -> 1.7392597 | T7: =IF(AB7>0,AB7/ABS(Q7)) -> 0.43621943 | U7: 11974 | V7: 43904.456 | W7: ME | X7: y | Z7: =IF(Y7="Y",AB7-R7,IF(X7="Y",AB7-Q7)) -> 139.072 | AA7: =(V7-B7)*24 -> 2.9333333 | AB7: 42.24 | AE7: =IF(A7<>"",A7&" - "&TEXT(B7, "dd/mm/yyyy hh:mm"),"") -> DAX - 14/03/2020 08:00 | AF7: 8 | AG7: 5 | AH7: 3 | AI7: 0 | AJ7: 0 | AK7: =SUM(AF7:AJ7) -> 16
A8: GOLD | B8: 43905.491 | C8: 2 | D8: S | E8: 7.5 | F8: 1302.25 | G8: 1315 | H8: 12.75 | O8: 1255 | P8: =IF(D8="B",O8-F8,IF(D8="S",F8-O8)) -> 47.25 | Q8: =-(E8*H8) -> -95.625 | R8: =E8*P8 -> 354.375 | S8: =ABS(R8/Q8) -> 3.7058824 | T8: =IF(AB8>0,AB8/ABS(Q8)) -> 3.7059346 | U8: 1255 | V8: 43905.689 | W8: T | X8: y | Z8: =IF(Y8="Y",AB8-R8,IF(X8="Y",AB8-Q8)) -> 450.005 | AA8: =(V8-B8)*24 -> 4.75 | AB8: 354.38 | AE8: =IF(A8<>"",A8&" - "&TEXT(B8, "dd/mm/yyyy hh:mm"),"") -> GOLD - 15/03/2020 11:47 | AF8: 8 | AG8: 5 | AH8: 3 | AI8: 0 | AJ8: 0 | AK8: =SUM(AF8:AJ8) -> 16
A10: Name
A11: Opening Balance | B11: 10000
A13: Trade Entry | U13: Trade Exit | AA13: Trading Statistics | AE13: Trade Sheets | AF13: Your Points System
A14: Asset | B14: Date | C14: Mood (1-5) | D14: B/S | E14: Lot Size | F14: Open @ | G14: Stop 1 | H14: Pip Risk | I14: Stop 2 | J14: Pip Risk | K14: Stop 3 | L14: Pip Risk | M14: Stop 4 | N14: Pip Risk | O14: Target | P14: Target in Pips | Q14: Initial Risk | R14: Initial Reward | S14: INITIAL RRR | T14: ACTUAL RRR | U14: Closed @ | V14: Date/Time | W14: Exit | X14: ME + Hit Stop | Y14: ME + Hit Target | Z14: P/L gained or lost | AA14: Duration (Hours) | AB14: Net P/L (£) | AC14: P/L (Pips) | AD14: Running P/L | AE14: Trade Sheet Name | AF14: Patterns (10) | AG14: S/R (10) | AH14: Candles (3) | AI14: RSI (3) | AJ14: Fibs (3) | AK14: TOTAL
A15: EURUSD | B15: 44777.354 | C15: 3 | D15: B | E15: 4.3 | F15: 1.0952 | G15: 1.0932 | H15: 20 | I15: 1.0952 | J15: 0 | K15: 1.0972 | O15: 1.1052 | P15: 100 | Q15: =-(E15*H15) -> -86 | R15: =E15*P15 -> 430 | S15: =ABS(R15/Q15) -> 5 | T15: =IF(AB15>0,AB15/ABS(Q15)) -> 1.744186 | U15: 1.1052 | V15: 44777.71 | W15: ME | Y15: Y | Z15: =IF(Y15="Y",AB15-R15,IF(X15="Y",AB15-Q15)) -> -280 | AA15: =(V15-B15)*24 -> 8.5333333 | AB15: 150 | AC15: 10 | AD15: =B11+AB15 -> 10150 | AE15: =IF(A15<>"",A15&" - "&TEXT(B15, "dd/mm/yyyy hh:mm"),"") -> EURUSD - 04/08/2022 08:30 | AF15: 8 | AG15: 5 | AH15: 3 | AI15: 0 | AJ15: 0 | AK15: =SUM(AF15:AJ15) -> 16
Q16: =-(E16*H16) -> 0 | R16: =E16*P16 -> 0 | S16: =ABS(R16/Q16) -> #DIV/0! | T16: =IF(AB16>0,AB16/ABS(Q16)) -> FALSE | Z16: =IF(Y16="Y",AB16-R16,IF(X16="Y",AB16-Q16)) -> FALSE | AA16: =(V16-B16)*24 -> 0 | AB16: -100 | AD16: =AD15+AB16 -> 10050 | AE16: =IF(A16<>"",A16&" - "&TEXT(B16, "dd/mm/yyyy hh:mm"),"") | AF16: 8 | AG16: 5 | AH16: 3 | AI16: 0 | AJ16: 0 | AK16: =SUM(AF16:AJ16) -> 16
Q17: =-(E17*H17) -> 0 | R17: =E17*P17 -> 0 | S17: =ABS(R17/Q17) -> #DIV/0! | T17: =IF(AB17>0,AB17/ABS(Q17)) -> #DIV/0! | Z17: =IF(Y17="Y",AB17-R17,IF(X17="Y",AB17-Q17)) -> FALSE | AA17: =(V17-B17)*24 -> 0 | AB17: 250 | AD17: =AD16+AB17 -> 10300 | AE17: =IF(A17<>"",A17&" - "&TEXT(B17, "dd/mm/yyyy hh:mm"),"") | AF17: 8 | AG17: 5 | AH17: 3 | AI17: 0 | AJ17: 0 | AK17: =SUM(AF17:AJ17) -> 16
Q18: =-(E18*H18) -> 0 | R18: =E18*P18 -> 0 | S18: =ABS(R18/Q18) -> #DIV/0! | T18: =IF(AB18>0,AB18/ABS(Q18)) -> FALSE | Z18: =IF(Y18="Y",AB18-R18,IF(X18="Y",AB18-Q18)) -> FALSE | AA18: =(V18-B18)*24 -> 0 | AB18: -150 | AD18: =AD17+AB18 -> 10150 | AE18: =IF(A18<>"",A18&" - "&TEXT(B18, "dd/mm/yyyy hh:mm"),"") | AF18: 8 | AG18: 5 | AH18: 3 | AI18: 0 | AJ18: 0 | AK18: =SUM(AF18:AJ18) -> 16
Q19: =-(E19*H19) -> 0 | R19: =E19*P19 -> 0 | S19: =ABS(R19/Q19) -> #DIV/0! | T19: =IF(AB19>0,AB19/ABS(Q19)) -> FALSE | Z19: =IF(Y19="Y",AB19-R19,IF(X19="Y",AB19-Q19)) -> FALSE | AA19: =(V19-B19)*24 -> 0 | AB19: -200 | AD19: =AD18+AB19 -> 9950 | AE19: =IF(A19<>"",A19&" - "&TEXT(B19, "dd/mm/yyyy hh:mm"),"") | AF19: 8 | AG19: 5 | AH19: 3 | AI19: 0 | AJ19: 0 | AK19: =SUM(AF19:AJ19) -> 16
Q20: =-(E20*H20) -> 0 | R20: =E20*P20 -> 0 | S20: =ABS(R20/Q20) -> #DIV/0! | T20: =IF(AB20>0,AB20/ABS(Q20)) -> FALSE | Z20: =IF(Y20="Y",AB20-R20,IF(X20="Y",AB20-Q20)) -> FALSE | AA20: =(V20-B20)*24 -> 0 | AD20: =AD19+AB20 -> 9950 | AE20: =IF(A20<>"",A20&" - "&TEXT(B20, "dd/mm/yyyy hh:mm"),"") | AF20: 8 | AG20: 5 | AH20: 3 | AI20: 0 | AJ20: 0 | AK20: =SUM(AF20:AJ20) -> 16
Q21: =-(E21*H21) -> 0 | R21: =E21*P21 -> 0 | S21: =ABS(R21/Q21) -> #DIV/0! | T21: =IF(AB21>0,AB21/ABS(Q21)) -> FALSE | Z21: =IF(Y21="Y",AB21-R21,IF(X21="Y",AB21-Q21)) -> FALSE | AA21: =(V21-B21)*24 -> 0 | AD21: =AD20+AB21 -> 9950 | AE21: =IF(A21<>"",A21&" - "&TEXT(B21, "dd/mm/yyyy hh:mm"),"") | AF21: 8 | AG21: 5 | AH21: 3 | AI21: 0 | AJ21: 0 | AK21: =SUM(AF21:AJ21) -> 16
Q22: =-(E22*H22) -> 0 | R22: =E22*P22 -> 0 | S22: =ABS(R22/Q22) -> #DIV/0! | T22: =IF(AB22>0,AB22/ABS(Q22)) -> FALSE | Z22: =IF(Y22="Y",AB22-R22,IF(X22="Y",AB22-Q22)) -> FALSE | AA22: =(V22-B22)*24 -> 0 | AD22: =AD21+AB22 -> 9950 | AE22: =IF(A22<>"",A22&" - "&TEXT(B22, "dd/mm/yyyy hh:mm"),"")
Q23: =-(E23*H23) -> 0 | R23: =E23*P23 -> 0 | S23: =ABS(R23/Q23) -> #DIV/0! | T23: =IF(AB23>0,AB23/ABS(Q23)) -> FALSE | Z23: =IF(Y23="Y",AB23-R23,IF(X23="Y",AB23-Q23)) -> FALSE | AA23: =(V23-B23)*24 -> 0 | AD23: =AD22+AB23 -> 9950 | AE23: =IF(A23<>"",A23&" - "&TEXT(B23, "dd/mm/yyyy hh:mm"),"")
Q24: =-(E24*H24) -> 0 | R24: =E24*P24 -> 0 | S24: =ABS(R24/Q24) -> #DIV/0! | T24: =IF(AB24>0,AB24/ABS(Q24)) -> FALSE | Z24: =IF(Y24="Y",AB24-R24,IF(X24="Y",AB24-Q24)) -> FALSE | AA24: =(V24-B24)*24 -> 0 | AD24: =AD23+AB24 -> 9950 | AE24: =IF(A24<>"",A24&" - "&TEXT(B24, "dd/mm/yyyy hh:mm"),"")
Q25: =-(E25*H25) -> 0 | R25: =E25*P25 -> 0 | S25: =ABS(R25/Q25) -> #DIV/0! | T25: =IF(AB25>0,AB25/ABS(Q25)) -> FALSE | Z25: =IF(Y25="Y",AB25-R25,IF(X25="Y",AB25-Q25)) -> FALSE | AA25: =(V25-B25)*24 -> 0 | AD25: =AD24+AB25 -> 9950 | AE25: =IF(A25<>"",A25&" - "&TEXT(B25, "dd/mm/yyyy hh:mm"),"")
Q26: =-(E26*H26) -> 0 | R26: =E26*P26 -> 0 | S26: =ABS(R26/Q26) -> #DIV/0! | T26: =IF(AB26>0,AB26/ABS(Q26)) -> FALSE | Z26: =IF(Y26="Y",AB26-R26,IF(X26="Y",AB26-Q26)) -> FALSE | AA26: =(V26-B26)*24 -> 0 | AD26: =AD25+AB26 -> 9950 | AE26: =IF(A26<>"",A26&" - "&TEXT(B26, "dd/mm/yyyy hh:mm"),"")
Q27: =-(E27*H27) -> 0 | R27: =E27*P27 -> 0 | S27: =ABS(R27/Q27) -> #DIV/0! | T27: =IF(AB27>0,AB27/ABS(Q27)) -> FALSE | Z27: =IF(Y27="Y",AB27-R27,IF(X27="Y",AB27-Q27)) -> FALSE | AA27: =(V27-B27)*24 -> 0 | AD27: =AD26+AB27 -> 9950 | AE27: =IF(A27<>"",A27&" - "&TEXT(B27, "dd/mm/yyyy hh:mm"),"")
Q28: =-(E28*H28) -> 0 | R28: =E28*P28 -> 0 | S28: =ABS(R28/Q28) -> #DIV/0! | T28: =IF(AB28>0,AB28/ABS(Q28)) -> FALSE | Z28: =IF(Y28="Y",AB28-R28,IF(X28="Y",AB28-Q28)) -> FALSE | AA28: =(V28-B28)*24 -> 0 | AD28: =AD27+AB28 -> 9950 | AE28: =IF(A28<>"",A28&" - "&TEXT(B28, "dd/mm/yyyy hh:mm"),"")
Q29: =-(E29*H29) -> 0 | R29: =E29*P29 -> 0 | S29: =ABS(R29/Q29) -> #DIV/0! | T29: =IF(AB29>0,AB29/ABS(Q29)) -> FALSE | Z29: =IF(Y29="Y",AB29-R29,IF(X29="Y",AB29-Q29)) -> FALSE | AA29: =(V29-B29)*24 -> 0 | AD29: =AD28+AB29 -> 9950 | AE29: =IF(A29<>"",A29&" - "&TEXT(B29, "dd/mm/yyyy hh:mm"),"")
Q30: =-(E30*H30) -> 0 | R30: =E30*P30 -> 0 | S30: =ABS(R30/Q30) -> #DIV/0! | T30: =IF(AB30>0,AB30/ABS(Q30)) -> FALSE | Z30: =IF(Y30="Y",AB30-R30,IF(X30="Y",AB30-Q30)) -> FALSE | AA30: =(V30-B30)*24 -> 0 | AD30: =AD29+AB30 -> 9950 | AE30: =IF(A30<>"",A30&" - "&TEXT(B30, "dd/mm/yyyy hh:mm"),"")
Q31: =-(E31*H31) -> 0 | R31: =E31*P31 -> 0 | S31: =ABS(R31/Q31) -> #DIV/0! | T31: =IF(AB31>0,AB31/ABS(Q31)) -> FALSE | Z31: =IF(Y31="Y",AB31-R31,IF(X31="Y",AB31-Q31)) -> FALSE | AA31: =(V31-B31)*24 -> 0 | AD31: =AD30+AB31 -> 9950 | AE31: =IF(A31<>"",A31&" - "&TEXT(B31, "dd/mm/yyyy hh:mm"),"")
Q32: =-(E32*H32) -> 0 | R32: =E32*P32 -> 0 | S32: =ABS(R32/Q32) -> #DIV/0! | T32: =IF(AB32>0,AB32/ABS(Q32)) -> FALSE | Z32: =IF(Y32="Y",AB32-R32,IF(X32="Y",AB32-Q32)) -> FALSE | AA32: =(V32-B32)*24 -> 0 | AD32: =AD31+AB32 -> 9950 | AE32: =IF(A32<>"",A32&" - "&TEXT(B32, "dd/mm/yyyy hh:mm"),"")
Q33: =-(E33*H33) -> 0 | R33: =E33*P33 -> 0 | S33: =ABS(R33/Q33) -> #DIV/0! | T33: =IF(AB33>0,AB33/ABS(Q33)) -> FALSE | Z33: =IF(Y33="Y",AB33-R33,IF(X33="Y",AB33-Q33)) -> FALSE | AA33: =(V33-B33)*24 -> 0 | AD33: =AD32+AB33 -> 9950 | AE33: =IF(A33<>"",A33&" - "&TEXT(B33, "dd/mm/yyyy hh:mm"),"")
... Q62: =-(E62*H62) -> 0 | R62: =E62*P62 -> 0 | S62: =ABS(R62/Q62) -> #DIV/0! | T62: =IF(AB62>0,AB62/ABS(Q62)) -> FALSE | Z62: =IF(Y62="Y",AB62-R62,IF(X62="Y",AB62-Q62)) -> FALSE | AA62: =(V62-B62)*24 -> 0 | AD62: =AD61+AB62 -> 9950 | AE62: =IF(A62<>"",A62&" - "&TEXT(B62, "dd/mm/yyyy hh:mm"),"")

Sheet Equity Curve
A1: Running P/L | B1: NOTE: Have to drag so to include all the data | E1: Equity Curve | I1: DO NOT TYPE OVER ANY GREY CELLS!!!
A2: ='Trade Blotter'!AD15 -> 10150
A3: ='Trade Blotter'!AD16 -> 10050
A4: ='Trade Blotter'!AD17 -> 10300
A5: ='Trade Blotter'!AD18 -> 10150
A6: ='Trade Blotter'!AD19 -> 9950
A7: ='Trade Blotter'!AD20 -> 9950
A8: ='Trade Blotter'!AD21 -> 9950
A9: ='Trade Blotter'!AD22 -> 9950
A10: ='Trade Blotter'!AD23 -> 9950
A11: ='Trade Blotter'!AD24 -> 9950
A12: ='Trade Blotter'!AD25 -> 9950
A13: ='Trade Blotter'!AD26 -> 9950
... A35: ='Trade Blotter'!AD48 -> 9950

Sheet PnL
K1: DO NOT TYPE OVER ANY GREY CELLS!!!
F2: PnL
A4: B/S | B4: Net PnL (£) | C4: NOTE: Have to copy Cells A% and B5 down to include all the data | M4: COUNT | N4: HIT | O4: AVG | P4: MAX | U4: Avg Long Win | V4: =AVERAGEIFS(B5:B50,A5:A50,"B",B5:B50,">0") -> 150
A5: ='Trade Blotter'!D15 -> B | B5: ='Trade Blotter'!AB15 -> 150 | L5: Winners | M5: =COUNTIF(B5:B50,">0") -> 2 | N5: =M5/(M5+M6) -> 0.4 | O5: =AVERAGEIF(B5:B50,">0",B5:B50) -> 200 | P5: =MAX(B5:B50) -> 250 | U5: Avg Short Win | V5: =AVERAGEIFS(B5:B50,A5:A50,"S",B5:B50,">0") -> #DIV/0!
A6: ='Trade Blotter'!D16 -> 0 | B6: ='Trade Blotter'!AB16 -> -100 | L6: Losers | M6: =COUNTIF(B5:B50,"<0") -> 3 | N6: =M6/(M5+M6) -> 0.6 | O6: =AVERAGEIF(B5:B50,"<0",B5:B50) -> -150 | P6: =MIN(B5:B50) -> -200 | U6: Avg Long Loss | V6: =AVERAGEIFS(B5:B50,A5:A50,"B",B5:B50,"<0") -> #DIV/0!
A7: ='Trade Blotter'!D17 -> 0 | B7: ='Trade Blotter'!AB17 -> 250 | L7: Total | M7: =SUM(M5:M6) -> 5 | U7: Avg Short Loss | V7: =AVERAGEIFS(B5:B50,A5:A50,"S",B5:B50,"<0") -> #DIV/0!
A8: ='Trade Blotter'!D18 -> 0 | B8: ='Trade Blotter'!AB18 -> -150
A9: ='Trade Blotter'!D19 -> 0 | B9: ='Trade Blotter'!AB19 -> -200
A10: ='Trade Blotter'!D20 -> 0 | B10: ='Trade Blotter'!AB20 -> 0
A11: ='Trade Blotter'!D21 -> 0 | B11: ='Trade Blotter'!AB21 -> 0
A12: ='Trade Blotter'!D22 -> 0 | B12: ='Trade Blotter'!AB22 -> 0
A13: ='Trade Blotter'!D23 -> 0 | B13: ='Trade Blotter'!AB23 -> 0
A14: ='Trade Blotter'!D23 -> 0 | B14: ='Trade Blotter'!AB23 -> 0
A15: ='Trade Blotter'!D24 -> 0 | B15: ='Trade Blotter'!AB24 -> 0
A16: ='Trade Blotter'!D25 -> 0 | B16: ='Trade Blotter'!AB25 -> 0
A17: ='Trade Blotter'!D26 -> 0 | B17: ='Trade Blotter'!AB26 -> 0
A18: ='Trade Blotter'!D27 -> 0 | B18: ='Trade Blotter'!AB27 -> 0
A19: ='Trade Blotter'!D28 -> 0 | B19: ='Trade Blotter'!AB28 -> 0
A20: ='Trade Blotter'!D29 -> 0 | B20: ='Trade Blotter'!AB29 -> 0
A21: ='Trade Blotter'!D30 -> 0 | B21: ='Trade Blotter'!AB30 -> 0
A22: ='Trade Blotter'!D31 -> 0 | B22: ='Trade Blotter'!AB31 -> 0
A23: ='Trade Blotter'!D32 -> 0 | B23: ='Trade Blotter'!AB32 -> 0
A24: ='Trade Blotter'!D33 -> 0 | B24: ='Trade Blotter'!AB33 -> 0
A25: ='Trade Blotter'!D34 -> 0 | B25: ='Trade Blotter'!AB34 -> 0
... A50: ='Trade Blotter'!D59 -> 0 | B50: ='Trade Blotter'!AB59 -> 0

Sheet RRR
E1: RRR | K1: DO NOT TYPE OVER ANY GREY CELLS!!!
A2: Initial RRR | B2: Actual RRR | C2: Net PnL (£)
A3: ='Trade Blotter'!S15 -> 5 | B3: ='Trade Blotter'!T15 -> 1.744186 | C3: ='Trade Blotter'!AB15 -> 150 | E3: Winning Position
A4: ='Trade Blotter'!S16 -> #DIV/0! | B4: ='Trade Blotter'!T16 -> FALSE | C4: ='Trade Blotter'!AB16 -> -100 | E4: On Entry | F4: On Exit
A5: ='Trade Blotter'!S17 -> #DIV/0! | B5: ='Trade Blotter'!T17 -> #DIV/0! | C5: ='Trade Blotter'!AB17 -> 250 | E5: =AVERAGEIF(C3:C50,">0",A3:A50) -> #DIV/0! | F5: =AVERAGEIF(C3:C50,">0",B3:B50) -> #DIV/0! | G5: =IF(F5<(0.9*E5), "Aim to run trades to full profit", "Good Work on Maximizing Profit") -> #DIV/0!
A6: ='Trade Blotter'!S18 -> #DIV/0! | B6: ='Trade Blotter'!T18 -> FALSE | C6: ='Trade Blotter'!AB18 -> -150
A7: ='Trade Blotter'!S19 -> #DIV/0! | B7: ='Trade Blotter'!T19 -> FALSE | C7: ='Trade Blotter'!AB19 -> -200
A8: ='Trade Blotter'!S20 -> #DIV/0! | B8: ='Trade Blotter'!T20 -> FALSE | C8: ='Trade Blotter'!AB20 -> 0
A9: ='Trade Blotter'!S21 -> #DIV/0! | B9: ='Trade Blotter'!T21 -> FALSE | C9: ='Trade Blotter'!AB21 -> 0
A10: ='Trade Blotter'!S22 -> #DIV/0! | B10: ='Trade Blotter'!T22 -> FALSE | C10: ='Trade Blotter'!AB22 -> 0
A11: ='Trade Blotter'!S23 -> #DIV/0! | B11: ='Trade Blotter'!T23 -> FALSE | C11: ='Trade Blotter'!AB23 -> 0
A12: ='Trade Blotter'!S24 -> #DIV/0! | B12: ='Trade Blotter'!T25 -> FALSE | C12: ='Trade Blotter'!AB25 -> 0
A13: ='Trade Blotter'!S26 -> #DIV/0! | B13: ='Trade Blotter'!T26 -> FALSE | C13: ='Trade Blotter'!AB26 -> 0
A14: ='Trade Blotter'!S27 -> #DIV/0! | B14: ='Trade Blotter'!T27 -> FALSE | C14: ='Trade Blotter'!AB27 -> 0
A15: ='Trade Blotter'!S28 -> #DIV/0! | B15: ='Trade Blotter'!T28 -> FALSE | C15: ='Trade Blotter'!AB28 -> 0
A16: ='Trade Blotter'!S29 -> #DIV/0! | B16: ='Trade Blotter'!T29 -> FALSE | C16: ='Trade Blotter'!AB29 -> 0
A17: ='Trade Blotter'!S30 -> #DIV/0! | B17: ='Trade Blotter'!T30 -> FALSE | C17: ='Trade Blotter'!AB30 -> 0
A18: ='Trade Blotter'!S31 -> #DIV/0! | B18: ='Trade Blotter'!T31 -> FALSE | C18: ='Trade Blotter'!AB31 -> 0
A19: ='Trade Blotter'!S32 -> #DIV/0! | B19: ='Trade Blotter'!T32 -> FALSE | C19: ='Trade Blotter'!AB32 -> 0
A20: ='Trade Blotter'!S33 -> #DIV/0! | B20: ='Trade Blotter'!T33 -> FALSE | C20: ='Trade Blotter'!AB33 -> 0
A21: ='Trade Blotter'!S34 -> #DIV/0! | B21: ='Trade Blotter'!T34 -> FALSE | C21: ='Trade Blotter'!AB34 -> 0
A22: ='Trade Blotter'!S35 -> #DIV/0! | B22: ='Trade Blotter'!T35 -> FALSE | C22: ='Trade Blotter'!AB35 -> 0
A23: ='Trade Blotter'!S36 -> #DIV/0! | B23: ='Trade Blotter'!T36 -> FALSE | C23: ='Trade Blotter'!AB36 -> 0
A24: ='Trade Blotter'!S37 -> #DIV/0! | B24: ='Trade Blotter'!T37 -> FALSE | C24: ='Trade Blotter'!AB37 -> 0
... A50: ='Trade Blotter'!S63 -> 0 | B50: ='Trade Blotter'!T63 -> 0 | C50: ='Trade Blotter'!AB63 -> 0

Sheet Asset Based
E1: Per Asset Stats | M1: DO NOT TYPE OVER ANY GREY CELLS!!!
A2: NOTE: Have to drag so to include all the data
A3: Assets Traded | B3: Net PnL (£)
A4: ='Trade Blotter'!A15 -> EURUSD | B4: ='Trade Blotter'!AB15 -> 150 | D4: Assets Traded | E4: Wins | G4: Losses | I4: Total trades
A5: ='Trade Blotter'!A16 -> 0 | B5: ='Trade Blotter'!AB16 -> -100 | E5: P/L | F5: Number | G5: P/L | H5: Number | I5: P/L | J5: Number
A6: ='Trade Blotter'!A17 -> 0 | B6: ='Trade Blotter'!AB17 -> 250 | D6: {=IFERROR(INDEX($A$4:$A$60, MATCH(0,COUNTIF($D$5:D5, $A$4:$A$60), 0)),"")} -> EURUSD | E6: =SUMIFS(B$4:B$60,A$4:A$60,D6,B$4:B$60,">0") -> 150 | F6: =COUNTIFS(A$4:A$60,D6,B$4:B$60,">0") -> 1 | G6: =SUMIFS(B$4:B$60,A$4:A$60,D6,B$4:B$60,"<0") -> 0 | H6: =COUNTIFS(A$4:A$60,D6,B$4:B$60,"<0") -> 0 | I6: =SUMIFS(B$4:B$60,A$4:A$60,D6) -> 150 | J6: =COUNTIF(A$4:A$60,D6) -> 1
A7: ='Trade Blotter'!A18 -> 0 | B7: ='Trade Blotter'!AB18 -> -150 | D7: {=IFERROR(INDEX($A$4:$A$60, MATCH(0,COUNTIF($D$5:D6, $A$4:$A$60), 0)),"")} -> 0 | E7: =SUMIFS(B$4:B$60,A$4:A$60,D7,B$4:B$60,">0") -> 250 | F7: =COUNTIFS(A$4:A$60,D7,B$4:B$60,">0") -> 1 | G7: =SUMIFS(B$4:B$60,A$4:A$60,D7,B$4:B$60,"<0") -> -450 | H7: =COUNTIFS(A$4:A$60,D7,B$4:B$60,"<0") -> 3 | I7: =SUMIFS(B$4:B$60,A$4:A$60,D7) -> -200 | J7: =COUNTIF(A$4:A$60,D7) -> 49
A8: ='Trade Blotter'!A19 -> 0 | B8: ='Trade Blotter'!AB19 -> -200 | D8: {=IFERROR(INDEX($A$4:$A$60, MATCH(0,COUNTIF($D$5:D7, $A$4:$A$60), 0)),"")} | E8: =SUMIFS(B$4:B$60,A$4:A$60,D8,B$4:B$60,">0") -> 0 | F8: =COUNTIFS(A$4:A$60,D8,B$4:B$60,">0") -> 0 | G8: =SUMIFS(B$4:B$60,A$4:A$60,D8,B$4:B$60,"<0") -> 0 | H8: =COUNTIFS(A$4:A$60,D8,B$4:B$60,"<0") -> 0 | I8: =SUMIFS(B$4:B$60,A$4:A$60,D8) -> 0 | J8: =COUNTIF(A$4:A$60,D8) -> 0
A9: ='Trade Blotter'!A20 -> 0 | B9: ='Trade Blotter'!AB20 -> 0 | D9: {=IFERROR(INDEX($A$4:$A$60, MATCH(0,COUNTIF($D$5:D8, $A$4:$A$60), 0)),"")} | E9: =SUMIFS(B$4:B$60,A$4:A$60,D9,B$4:B$60,">0") -> 0 | F9: =COUNTIFS(A$4:A$60,D9,B$4:B$60,">0") -> 0 | G9: =SUMIFS(B$4:B$60,A$4:A$60,D9,B$4:B$60,"<0") -> 0 | H9: =COUNTIFS(A$4:A$60,D9,B$4:B$60,"<0") -> 0 | I9: =SUMIFS(B$4:B$60,A$4:A$60,D9) -> 0 | J9: =COUNTIF(A$4:A$60,D9) -> 0
A10: ='Trade Blotter'!A21 -> 0 | B10: ='Trade Blotter'!AB21 -> 0 | D10: {=IFERROR(INDEX($A$4:$A$60, MATCH(0,COUNTIF($D$5:D9, $A$4:$A$60), 0)),"")} | E10: =SUMIFS(B$4:B$60,A$4:A$60,D10,B$4:B$60,">0") -> 0 | F10: =COUNTIFS(A$4:A$60,D10,B$4:B$60,">0") -> 0 | G10: =SUMIFS(B$4:B$60,A$4:A$60,D10,B$4:B$60,"<0") -> 0 | H10: =COUNTIFS(A$4:A$60,D10,B$4:B$60,"<0") -> 0 | I10: =SUMIFS(B$4:B$60,A$4:A$60,D10) -> 0 | J10: =COUNTIF(A$4:A$60,D10) -> 0
A11: ='Trade Blotter'!A22 -> 0 | B11: ='Trade Blotter'!AB22 -> 0 | D11: {=IFERROR(INDEX($A$4:$A$60, MATCH(0,COUNTIF($D$5:D10, $A$4:$A$60), 0)),"")} | E11: =SUMIFS(B$4:B$60,A$4:A$60,D11,B$4:B$60,">0") -> 0 | F11: =COUNTIFS(A$4:A$60,D11,B$4:B$60,">0") -> 0 | G11: =SUMIFS(B$4:B$60,A$4:A$60,D11,B$4:B$60,"<0") -> 0 | H11: =COUNTIFS(A$4:A$60,D11,B$4:B$60,"<0") -> 0 | I11: =SUMIFS(B$4:B$60,A$4:A$60,D11) -> 0 | J11: 0
A12: ='Trade Blotter'!A23 -> 0 | B12: ='Trade Blotter'!AB23 -> 0 | D12: {=IFERROR(INDEX($A$4:$A$60, MATCH(0,COUNTIF($D$5:D11, $A$4:$A$60), 0)),"")} | E12: =SUMIFS(B$4:B$60,A$4:A$60,D12,B$4:B$60,">0") -> 0 | F12: =COUNTIFS(A$4:A$60,D12,B$4:B$60,">0") -> 0 | G12: =SUMIFS(B$4:B$60,A$4:A$60,D12,B$4:B$60,"<0") -> 0 | H12: =COUNTIFS(A$4:A$60,D12,B$4:B$60,"<0") -> 0 | I12: =SUMIFS(B$4:B$60,A$4:A$60,D12) -> 0 | J12: =COUNTIF(A$4:A$60,D12) -> 0
A13: ='Trade Blotter'!A24 -> 0 | B13: ='Trade Blotter'!AB24 -> 0 | D13: {=IFERROR(INDEX($A$4:$A$60, MATCH(0,COUNTIF($D$5:D12, $A$4:$A$60), 0)),"")} | E13: =SUMIFS(B$4:B$60,A$4:A$60,D13,B$4:B$60,">0") -> 0 | F13: =COUNTIFS(A$4:A$60,D13,B$4:B$60,">0") -> 0 | G13: =SUMIFS(B$4:B$60,A$4:A$60,D13,B$4:B$60,"<0") -> 0 | H13: =COUNTIFS(A$4:A$60,D13,B$4:B$60,"<0") -> 0 | I13: =SUMIFS(B$4:B$60,A$4:A$60,D13) -> 0 | J13: =COUNTIF(A$4:A$60,D13) -> 0
A14: ='Trade Blotter'!A25 -> 0 | B14: ='Trade Blotter'!AB25 -> 0 | D14: {=IFERROR(INDEX($A$4:$A$60, MATCH(0,COUNTIF($D$5:D13, $A$4:$A$60), 0)),"")} | E14: =SUMIFS(B$4:B$60,A$4:A$60,D14,B$4:B$60,">0") -> 0 | F14: =COUNTIFS(A$4:A$60,D14,B$4:B$60,">0") -> 0 | G14: =SUMIFS(B$4:B$60,A$4:A$60,D14,B$4:B$60,"<0") -> 0 | H14: =COUNTIFS(A$4:A$60,D14,B$4:B$60,"<0") -> 0 | I14: =SUMIFS(B$4:B$60,A$4:A$60,D14) -> 0 | J14: =COUNTIF(A$4:A$60,D14) -> 0
A15: ='Trade Blotter'!A24 -> 0 | B15: ='Trade Blotter'!AB26 -> 0 | D15: {=IFERROR(INDEX($A$4:$A$60, MATCH(0,COUNTIF($D$5:D14, $A$4:$A$60), 0)),"")} | E15: =SUMIFS(B$4:B$60,A$4:A$60,D15,B$4:B$60,">0") -> 0 | F15: =COUNTIFS(A$4:A$60,D15,B$4:B$60,">0") -> 0 | G15: =SUMIFS(B$4:B$60,A$4:A$60,D15,B$4:B$60,"<0") -> 0 | H15: =COUNTIFS(A$4:A$60,D15,B$4:B$60,"<0") -> 0 | I15: =SUMIFS(B$4:B$60,A$4:A$60,D15) -> 0 | J15: =COUNTIF(A$4:A$60,D15) -> 0
A16: ='Trade Blotter'!A25 -> 0 | B16: ='Trade Blotter'!AB25 -> 0 | D16: {=IFERROR(INDEX($A$4:$A$60, MATCH(0,COUNTIF($D$5:D15, $A$4:$A$60), 0)),"")} | E16: =SUMIFS(B$4:B$60,A$4:A$60,D16,B$4:B$60,">0") -> 0 | F16: =COUNTIFS(A$4:A$60,D16,B$4:B$60,">0") -> 0 | G16: =SUMIFS(B$4:B$60,A$4:A$60,D16,B$4:B$60,"<0") -> 0 | H16: =COUNTIFS(A$4:A$60,D16,B$4:B$60,"<0") -> 0 | I16: =SUMIFS(B$4:B$60,A$4:A$60,D16) -> 0 | J16: =COUNTIF(A$4:A$60,D16) -> 0
A17: ='Trade Blotter'!A26 -> 0 | B17: ='Trade Blotter'!AB26 -> 0 | D17: {=IFERROR(INDEX($A$4:$A$60, MATCH(0,COUNTIF($D$5:D16, $A$4:$A$60), 0)),"")} | E17: =SUMIFS(B$4:B$60,A$4:A$60,D17,B$4:B$60,">0") -> 0 | F17: =COUNTIFS(A$4:A$60,D17,B$4:B$60,">0") -> 0 | G17: =SUMIFS(B$4:B$60,A$4:A$60,D17,B$4:B$60,"<0") -> 0 | H17: =COUNTIFS(A$4:A$60,D17,B$4:B$60,"<0") -> 0 | I17: =SUMIFS(B$4:B$60,A$4:A$60,D17) -> 0 | J17: =COUNTIF(A$4:A$60,D17) -> 0
A18: ='Trade Blotter'!A27 -> 0 | B18: ='Trade Blotter'!AB27 -> 0 | D18: {=IFERROR(INDEX($A$4:$A$60, MATCH(0,COUNTIF($D$5:D17, $A$4:$A$60), 0)),"")} | E18: =SUMIFS(B$4:B$60,A$4:A$60,D18,B$4:B$60,">0") -> 0 | F18: =COUNTIFS(A$4:A$60,D18,B$4:B$60,">0") -> 0 | G18: =SUMIFS(B$4:B$60,A$4:A$60,D18,B$4:B$60,"<0") -> 0 | H18: =COUNTIFS(A$4:A$60,D18,B$4:B$60,"<0") -> 0 | I18: =SUMIFS(B$4:B$60,A$4:A$60,D18) -> 0 | J18: =COUNTIF(A$4:A$60,D18) -> 0
A19: ='Trade Blotter'!A28 -> 0 | B19: ='Trade Blotter'!AB28 -> 0 | D19: {=IFERROR(INDEX($A$4:$A$60, MATCH(0,COUNTIF($D$5:D18, $A$4:$A$60), 0)),"")} | E19: =SUMIFS(B$4:B$60,A$4:A$60,D19,B$4:B$60,">0") -> 0 | F19: =COUNTIFS(A$4:A$60,D19,B$4:B$60,">0") -> 0 | G19: =SUMIFS(B$4:B$60,A$4:A$60,D19,B$4:B$60,"<0") -> 0 | H19: =COUNTIFS(A$4:A$60,D19,B$4:B$60,"<0") -> 0 | I19: =SUMIFS(B$4:B$60,A$4:A$60,D19) -> 0 | J19: =COUNTIF(A$4:A$60,D19) -> 0
A20: ='Trade Blotter'!A29 -> 0 | B20: ='Trade Blotter'!AB29 -> 0 | D20: {=IFERROR(INDEX($A$4:$A$60, MATCH(0,COUNTIF($D$5:D19, $A$4:$A$60), 0)),"")} | E20: =SUMIFS(B$4:B$60,A$4:A$60,D20,B$4:B$60,">0") -> 0 | F20: =COUNTIFS(A$4:A$60,D20,B$4:B$60,">0") -> 0 | G20: =SUMIFS(B$4:B$60,A$4:A$60,D20,B$4:B$60,"<0") -> 0 | H20: =COUNTIFS(A$4:A$60,D20,B$4:B$60,"<0") -> 0 | I20: =SUMIFS(B$4:B$60,A$4:A$60,D20) -> 0 | J20: =COUNTIF(A$4:A$60,D20) -> 0
A21: ='Trade Blotter'!A30 -> 0 | B21: ='Trade Blotter'!AB30 -> 0 | D21: {=IFERROR(INDEX($A$4:$A$60, MATCH(0,COUNTIF($D$5:D20, $A$4:$A$60), 0)),"")} | E21: =SUMIFS(B$4:B$60,A$4:A$60,D21,B$4:B$60,">0") -> 0 | F21: =COUNTIFS(A$4:A$60,D21,B$4:B$60,">0") -> 0 | G21: =SUMIFS(B$4:B$60,A$4:A$60,D21,B$4:B$60,"<0") -> 0 | H21: =COUNTIFS(A$4:A$60,D21,B$4:B$60,"<0") -> 0 | I21: =SUMIFS(B$4:B$60,A$4:A$60,D21) -> 0 | J21: =COUNTIF(A$4:A$60,D21) -> 0
A22: ='Trade Blotter'!A31 -> 0 | B22: ='Trade Blotter'!AB31 -> 0 | D22: {=IFERROR(INDEX($A$4:$A$60, MATCH(0,COUNTIF($D$5:D21, $A$4:$A$60), 0)),"")} | E22: =SUMIFS(B$4:B$60,A$4:A$60,D22,B$4:B$60,">0") -> 0 | F22: =COUNTIFS(A$4:A$60,D22,B$4:B$60,">0") -> 0 | G22: =SUMIFS(B$4:B$60,A$4:A$60,D22,B$4:B$60,"<0") -> 0 | H22: =COUNTIFS(A$4:A$60,D22,B$4:B$60,"<0") -> 0 | I22: =SUMIFS(B$4:B$60,A$4:A$60,D22) -> 0 | J22: =COUNTIF(A$4:A$60,D22) -> 0
A23: ='Trade Blotter'!A32 -> 0 | B23: ='Trade Blotter'!AB32 -> 0 | D23: {=IFERROR(INDEX($A$4:$A$60, MATCH(0,COUNTIF($D$5:D22, $A$4:$A$60), 0)),"")} | E23: =SUMIFS(B$4:B$60,A$4:A$60,D23,B$4:B$60,">0") -> 0 | F23: =COUNTIFS(A$4:A$60,D23,B$4:B$60,">0") -> 0 | G23: =SUMIFS(B$4:B$60,A$4:A$60,D23,B$4:B$60,"<0") -> 0 | H23: =COUNTIFS(A$4:A$60,D23,B$4:B$60,"<0") -> 0 | I23: =SUMIFS(B$4:B$60,A$4:A$60,D23) -> 0 | J23: =COUNTIF(A$4:A$60,D23) -> 0
A24: ='Trade Blotter'!A33 -> 0 | B24: ='Trade Blotter'!AB33 -> 0 | D24: {=IFERROR(INDEX($A$4:$A$60, MATCH(0,COUNTIF($D$5:D23, $A$4:$A$60), 0)),"")} | E24: =SUMIFS(B$4:B$60,A$4:A$60,D24,B$4:B$60,">0") -> 0 | F24: =COUNTIFS(A$4:A$60,D24,B$4:B$60,">0") -> 0 | G24: =SUMIFS(B$4:B$60,A$4:A$60,D24,B$4:B$60,"<0") -> 0 | H24: =COUNTIFS(A$4:A$60,D24,B$4:B$60,"<0") -> 0 | I24: =SUMIFS(B$4:B$60,A$4:A$60,D24) -> 0 | J24: =COUNTIF(A$4:A$60,D24) -> 0
A25: ='Trade Blotter'!A34 -> 0 | B25: ='Trade Blotter'!AB34 -> 0 | D25: {=IFERROR(INDEX($A$4:$A$60, MATCH(0,COUNTIF($D$5:D24, $A$4:$A$60), 0)),"")} | E25: =SUMIFS(B$4:B$60,A$4:A$60,D25,B$4:B$60,">0") -> 0 | F25: =COUNTIFS(A$4:A$60,D25,B$4:B$60,">0") -> 0 | G25: =SUMIFS(B$4:B$60,A$4:A$60,D25,B$4:B$60,"<0") -> 0 | H25: =COUNTIFS(A$4:A$60,D25,B$4:B$60,"<0") -> 0 | I25: =SUMIFS(B$4:B$60,A$4:A$60,D25) -> 0 | J25: =COUNTIF(A$4:A$60,D25) -> 0
A26: ='Trade Blotter'!A35 -> 0 | B26: ='Trade Blotter'!AB35 -> 0 | D26: {=IFERROR(INDEX($A$4:$A$60, MATCH(0,COUNTIF($D$5:D25, $A$4:$A$60), 0)),"")} | E26: =SUMIFS(B$4:B$60,A$4:A$60,D26,B$4:B$60,">0") -> 0 | F26: =COUNTIFS(A$4:A$60,D26,B$4:B$60,">0") -> 0 | G26: =SUMIFS(B$4:B$60,A$4:A$60,D26,B$4:B$60,"<0") -> 0 | H26: =COUNTIFS(A$4:A$60,D26,B$4:B$60,"<0") -> 0 | I26: =SUMIFS(B$4:B$60,A$4:A$60,D26) -> 0 | J26: =COUNTIF(A$4:A$60,D26) -> 0
A27: ='Trade Blotter'!A36 -> 0 | B27: ='Trade Blotter'!AB36 -> 0 | D27: {=IFERROR(INDEX($A$4:$A$60, MATCH(0,COUNTIF($D$5:D26, $A$4:$A$60), 0)),"")}
A28: ='Trade Blotter'!A37 -> 0 | B28: ='Trade Blotter'!AB37 -> 0 | D28: {=IFERROR(INDEX($A$4:$A$60, MATCH(0,COUNTIF($D$5:D27, $A$4:$A$60), 0)),"")}
A29: ='Trade Blotter'!A38 -> 0 | B29: ='Trade Blotter'!AB38 -> 0 | D29: {=IFERROR(INDEX($A$4:$A$60, MATCH(0,COUNTIF($D$5:D28, $A$4:$A$60), 0)),"")}
A30: ='Trade Blotter'!A39 -> 0 | B30: ='Trade Blotter'!AB39 -> 0 | D30: {=IFERROR(INDEX($A$4:$A$60, MATCH(0,COUNTIF($D$5:D29, $A$4:$A$60), 0)),"")}
A31: ='Trade Blotter'!A40 -> 0 | B31: ='Trade Blotter'!AB40 -> 0 | D31: {=IFERROR(INDEX($A$4:$A$60, MATCH(0,COUNTIF($D$5:D30, $A$4:$A$60), 0)),"")}
A32: ='Trade Blotter'!A41 -> 0 | B32: ='Trade Blotter'!AB41 -> 0 | D32: {=IFERROR(INDEX($A$4:$A$60, MATCH(0,COUNTIF($D$5:D31, $A$4:$A$60), 0)),"")}
A33: ='Trade Blotter'!A42 -> 0 | B33: ='Trade Blotter'!AB42 -> 0 | D33: {=IFERROR(INDEX($A$4:$A$60, MATCH(0,COUNTIF($D$5:D32, $A$4:$A$60), 0)),"")}
A34: ='Trade Blotter'!A43 -> 0 | B34: ='Trade Blotter'!AB43 -> 0 | D34: {=IFERROR(INDEX($A$4:$A$60, MATCH(0,COUNTIF($D$5:D33, $A$4:$A$60), 0)),"")}
A35: ='Trade Blotter'!A44 -> 0 | B35: ='Trade Blotter'!AB44 -> 0 | D35: {=IFERROR(INDEX($A$4:$A$60, MATCH(0,COUNTIF($D$5:D34, $A$4:$A$60), 0)),"")}
A36: ='Trade Blotter'!A45 -> 0 | B36: ='Trade Blotter'!AB45 -> 0 | D36: {=IFERROR(INDEX($A$4:$A$60, MATCH(0,COUNTIF($D$5:D35, $A$4:$A$60), 0)),"")}
A37: ='Trade Blotter'!A46 -> 0 | B37: ='Trade Blotter'!AB46 -> 0 | D37: {=IFERROR(INDEX($A$4:$A$60, MATCH(0,COUNTIF($D$5:D36, $A$4:$A$60), 0)),"")}
A38: ='Trade Blotter'!A47 -> 0 | B38: ='Trade Blotter'!AB47 -> 0 | D38: {=IFERROR(INDEX($A$4:$A$60, MATCH(0,COUNTIF($D$5:D37, $A$4:$A$60), 0)),"")}
A39: ='Trade Blotter'!A48 -> 0 | B39: ='Trade Blotter'!AB48 -> 0 | D39: {=IFERROR(INDEX($A$4:$A$60, MATCH(0,COUNTIF($D$5:D38, $A$4:$A$60), 0)),"")}
A40: ='Trade Blotter'!A49 -> 0 | B40: ='Trade Blotter'!AB49 -> 0
...

Sheet Other Stats
O1: DO NOT TYPE OVER ANY GREY CELLS!!!
F2: Other Stats
B3: Exit | K3: Days Traded | U3: Times Traded | AE3: Trade Duration (Hours)
B5: S1 | C5: =COUNTIF(B32:B60,"S1") -> 0 | K5: Monday | L5: =COUNTIF(L32:L60,"Monday") -> 0 | U5: 6:00-8:00 | V5: =COUNTIFS(V32:V60,">=6",V32:V60,"<=8") -> 1 | AF5: Average
B6: S2+ | C6: =COUNTIF(B32:B60,"S2+") -> 0 | K6: Tuesday | L6: =COUNTIF(L32:L60,"Tuesday") -> 0 | U6: 8:00-10:00 | V6: =COUNTIFS(V32:V60,">8",V32:V60,"<=10") -> 0 | AE6: Long Win | AF6: =AVERAGEIFS(AF32:AF60,AE32:AE60,"B",AI32:AI60,">0") -> 8.5333333
B7: T | C7: =COUNTIF(B32:B60,"T") -> 0 | K7: Wednesday | L7: =COUNTIF(L32:L60,"Wednesday") -> 0 | U7: 10:00-12:00 | V7: =COUNTIFS(V32:V60,">10",V32:V60,"<=12") -> 0 | AE7: Short Win | AF7: =AVERAGEIFS(AF32:AF60,AE32:AE60,"S",AI32:AI60,">0") -> #DIV/0!
B8: ME | C8: =COUNTIF(B32:B60,"ME") -> 1 | K8: Thursday | L8: =COUNTIF(L32:L60,"Thursday") -> 1 | U8: 12:00-14:00 | V8: =COUNTIFS(V32:V60,">12",V32:V60,"<=14") -> 0 | AE8: Long Loss | AF8: =AVERAGEIFS(AF32:AF60,AE32:AE60,"B",AI32:AI60,"<0") -> #DIV/0!
B9: Total | C9: =SUM(C5:C8) -> 1 | K9: Friday | L9: =COUNTIF(L32:L60,"Friday") -> 0 | U9: 14:00-16:00 | V9: =COUNTIFS(V32:V60,">14",V32:V60,"<=16") -> 0 | AE9: Short Loss | AF9: =AVERAGEIFS(AF32:AF60,AE32:AE60,"S",AI32:AI60,"<0") -> #DIV/0!
U10: 16:00-18:00 | V10: =COUNTIFS(V32:V60,">16",V32:V60,"<=18") -> 0
U11: 18:00-20:00 | V11: =COUNTIFS(V32:V60,">18",V32:V60,"<=20") -> 0
U12: 22:00-00:00 | V12: =COUNTIFS(V32:V60,">20",V32:V60,"<=00") -> 0
U13: 00:00-02:00 | V13: =COUNTIFS(V32:V60,">00",V32:V60,"<=02") -> 0
U14: 02:00-04:00 | V14: =COUNTIFS(V32:V60,">02",V32:V60,"<=04") -> 0
U15: 04:00-06:00 | V15: =COUNTIFS(V32:V60,">04",V32:V60,"<=06") -> 0
B31: Exit | K31: Days Traded | U31: Times Traded | AE31: B/S | AF31: Trade Duration (Hours) | AI31: Net P/L
B32: ='Trade Blotter'!W15 -> ME | K32: ='Trade Blotter'!B15 -> 44777.354 | L32: =TEXT(K32,"dddd") -> Thursday | U32: ='Trade Blotter'!B15 -> 44777.354 | V32: =HOUR(U32) -> 8 | AE32: ='Trade Blotter'!D15 -> B | AF32: ='Trade Blotter'!AA15 -> 8.5333333 | AI32: ='Trade Blotter'!AB15 -> 150
B33: ='Trade Blotter'!W16 -> 0 | K33: ='Trade Blotter'!B16 -> 0 | L33: =TEXT(K33,"dddd") -> Saturday | U33: ='Trade Blotter'!B16 -> 0 | V33: =HOUR(U33) -> 0 | AE33: ='Trade Blotter'!D16 -> 0 | AF33: ='Trade Blotter'!AA16 -> 0 | AI33: ='Trade Blotter'!AB16 -> -100
B34: ='Trade Blotter'!W17 -> 0 | K34: ='Trade Blotter'!B17 -> 0 | L34: =TEXT(K34,"dddd") -> Saturday | U34: ='Trade Blotter'!B17 -> 0 | V34: =HOUR(U34) -> 0 | AE34: ='Trade Blotter'!D17 -> 0 | AF34: ='Trade Blotter'!AA17 -> 0 | AI34: ='Trade Blotter'!AB17 -> 250
B35: ='Trade Blotter'!W18 -> 0 | K35: ='Trade Blotter'!B18 -> 0 | L35: =TEXT(K35,"dddd") -> Saturday | U35: ='Trade Blotter'!B18 -> 0 | V35: =HOUR(U35) -> 0 | AE35: ='Trade Blotter'!D18 -> 0 | AF35: ='Trade Blotter'!AA18 -> 0 | AI35: ='Trade Blotter'!AB18 -> -150
B36: ='Trade Blotter'!W19 -> 0 | K36: ='Trade Blotter'!B19 -> 0 | L36: =TEXT(K36,"dddd") -> Saturday | U36: ='Trade Blotter'!B19 -> 0 | V36: =HOUR(U36) -> 0 | AE36: ='Trade Blotter'!D19 -> 0 | AF36: ='Trade Blotter'!AA19 -> 0 | AI36: ='Trade Blotter'!AB19 -> -200
B37: ='Trade Blotter'!W20 -> 0 | K37: ='Trade Blotter'!B20 -> 0 | L37: =TEXT(K37,"dddd") -> Saturday | U37: ='Trade Blotter'!B20 -> 0 | V37: =HOUR(U37) -> 0 | AE37: ='Trade Blotter'!D20 -> 0 | AF37: ='Trade Blotter'!AA20 -> 0 | AI37: ='Trade Blotter'!AB20 -> 0
B38: ='Trade Blotter'!W21 -> 0 | K38: ='Trade Blotter'!B21 -> 0 | L38: =TEXT(K38,"dddd") -> Saturday | U38: ='Trade Blotter'!B21 -> 0 | V38: =HOUR(U38) -> 0 | AE38: ='Trade Blotter'!D21 -> 0 | AF38: ='Trade Blotter'!AA21 -> 0 | AI38: ='Trade Blotter'!AB21 -> 0
B39: ='Trade Blotter'!W22 -> 0 | K39: ='Trade Blotter'!B22 -> 0 | L39: =TEXT(K39,"dddd") -> Saturday | U39: ='Trade Blotter'!B22 -> 0 | V39: =HOUR(U39) -> 0 | AE39: ='Trade Blotter'!D22 -> 0 | AF39: ='Trade Blotter'!AA22 -> 0 | AI39: ='Trade Blotter'!AB22 -> 0
B40: ='Trade Blotter'!W23 -> 0 | K40: ='Trade Blotter'!B23 -> 0 | L40: =TEXT(K40,"dddd") -> Saturday | U40: ='Trade Blotter'!B23 -> 0 | V40: =HOUR(U40) -> 0 | AE40: ='Trade Blotter'!D23 -> 0 | AF40: ='Trade Blotter'!AA23 -> 0 | AI40: ='Trade Blotter'!AB23 -> 0
B41: ='Trade Blotter'!W24 -> 0 | K41: ='Trade Blotter'!B24 -> 0 | L41: =TEXT(K41,"dddd") -> Saturday | U41: ='Trade Blotter'!B24 -> 0 | V41: =HOUR(U41) -> 0 | AE41: ='Trade Blotter'!D24 -> 0 | AF41: ='Trade Blotter'!AA24 -> 0 | AI41: ='Trade Blotter'!AB24 -> 0
B42: ='Trade Blotter'!W25 -> 0 | K42: ='Trade Blotter'!B25 -> 0 | L42: =TEXT(K42,"dddd") -> Saturday | U42: ='Trade Blotter'!B25 -> 0 | V42: =HOUR(U42) -> 0 | AE42: ='Trade Blotter'!D25 -> 0 | AF42: ='Trade Blotter'!AA23 -> 0 | AI42: ='Trade Blotter'!AB25 -> 0
B43: ='Trade Blotter'!W24 -> 0 | K43: ='Trade Blotter'!B24 -> 0 | L43: =TEXT(K43,"dddd") -> Saturday | U43: ='Trade Blotter'!B24 -> 0 | V43: =HOUR(U43) -> 0 | AE43: ='Trade Blotter'!D24 -> 0 | AF43: ='Trade Blotter'!AA24 -> 0 | AI43: ='Trade Blotter'!AB24 -> 0
B44: ='Trade Blotter'!W25 -> 0 | K44: ='Trade Blotter'!B25 -> 0 | L44: =TEXT(K44,"dddd") -> Saturday | U44: ='Trade Blotter'!B25 -> 0 | V44: =HOUR(U44) -> 0 | AE44: ='Trade Blotter'!D25 -> 0 | AF44: ='Trade Blotter'!AA25 -> 0 | AI44: ='Trade Blotter'!AB25 -> 0
B45: ='Trade Blotter'!W26 -> 0 | K45: ='Trade Blotter'!B26 -> 0 | L45: =TEXT(K45,"dddd") -> Saturday | U45: ='Trade Blotter'!B26 -> 0 | V45: =HOUR(U45) -> 0 | AE45: ='Trade Blotter'!D26 -> 0 | AF45: ='Trade Blotter'!AA26 -> 0 | AI45: ='Trade Blotter'!AB26 -> 0
B46: ='Trade Blotter'!W27 -> 0 | K46: ='Trade Blotter'!B27 -> 0 | L46: =TEXT(K46,"dddd") -> Saturday | U46: ='Trade Blotter'!B27 -> 0 | V46: =HOUR(U46) -> 0 | AE46: ='Trade Blotter'!D27 -> 0 | AF46: ='Trade Blotter'!AA27 -> 0 | AI46: ='Trade Blotter'!AB27 -> 0
B47: ='Trade Blotter'!W28 -> 0 | K47: ='Trade Blotter'!B28 -> 0 | L47: =TEXT(K47,"dddd") -> Saturday | U47: ='Trade Blotter'!B28 -> 0 | V47: =HOUR(U47) -> 0 | AE47: ='Trade Blotter'!D28 -> 0 | AF47: ='Trade Blotter'!AA28 -> 0 | AI47: ='Trade Blotter'!AB28 -> 0
B48: ='Trade Blotter'!W29 -> 0 | K48: ='Trade Blotter'!B29 -> 0 | L48: =TEXT(K48,"dddd") -> Saturday | U48: ='Trade Blotter'!B29 -> 0 | V48: =HOUR(U48) -> 0 | AE48: ='Trade Blotter'!D29 -> 0 | AF48: ='Trade Blotter'!AA29 -> 0 | AI48: ='Trade Blotter'!AB29 -> 0
B49: ='Trade Blotter'!W30 -> 0 | K49: ='Trade Blotter'!B30 -> 0 | L49: =TEXT(K49,"dddd") -> Saturday | U49: ='Trade Blotter'!B30 -> 0 | V49: =HOUR(U49) -> 0 | AE49: ='Trade Blotter'!D30 -> 0 | AF49: ='Trade Blotter'!AA30 -> 0 | AI49: ='Trade Blotter'!AB30 -> 0
B50: ='Trade Blotter'!W31 -> 0 | K50: ='Trade Blotter'!B31 -> 0 | L50: =TEXT(K50,"dddd") -> Saturday | U50: ='Trade Blotter'!B31 -> 0 | V50: =HOUR(U50) -> 0 | AE50: ='Trade Blotter'!D31 -> 0 | AF50: ='Trade Blotter'!AA31 -> 0 | AI50: ='Trade Blotter'!AB31 -> 0
B51: ='Trade Blotter'!W32 -> 0 | K51: ='Trade Blotter'!B32 -> 0 | L51: =TEXT(K51,"dddd") -> Saturday | U51: ='Trade Blotter'!B32 -> 0 | V51: =HOUR(U51) -> 0 | AE51: ='Trade Blotter'!D32 -> 0 | AF51: ='Trade Blotter'!AA32 -> 0 | AI51: ='Trade Blotter'!AB32 -> 0
B52: ='Trade Blotter'!W33 -> 0 | K52: ='Trade Blotter'!B33 -> 0 | L52: =TEXT(K52,"dddd") -> Saturday | U52: ='Trade Blotter'!B33 -> 0 | V52: =HOUR(U52) -> 0 | AE52: ='Trade Blotter'!D33 -> 0 | AF52: ='Trade Blotter'!AA33 -> 0 | AI52: ='Trade Blotter'!AB33 -> 0
B53: ='Trade Blotter'!W34 -> 0 | K53: ='Trade Blotter'!B34 -> 0 | L53: =TEXT(K53,"dddd") -> Saturday | U53: ='Trade Blotter'!B34 -> 0 | V53: =HOUR(U53) -> 0 | AE53: ='Trade Blotter'!D34 -> 0 | AF53: ='Trade Blotter'!AA34 -> 0 | AI53: ='Trade Blotter'!AB34 -> 0
B54: ='Trade Blotter'!W35 -> 0 | K54: ='Trade Blotter'!B35 -> 0 | L54: =TEXT(K54,"dddd") -> Saturday | U54: ='Trade Blotter'!B35 -> 0 | V54: =HOUR(U54) -> 0 | AE54: ='Trade Blotter'!D35 -> 0 | AF54: ='Trade Blotter'!AA35 -> 0 | AI54: ='Trade Blotter'!AB35 -> 0
... B60: ='Trade Blotter'!W41 -> 0 | K60: ='Trade Blotter'!B41 -> 0 | L60: =TEXT(K60,"dddd") -> Saturday | U60: ='Trade Blotter'!B41 -> 0 | V60: =HOUR(U60) -> 0 | AE60: ='Trade Blotter'!D41 -> 0 | AF60: ='Trade Blotter'!AA41 -> 0 | AI60: ='Trade Blotter'!AB41 -> 0
